Workbook

Sheet Dashboard
A1: HR Operations Dashboard
A2: Sample reporting cycle — data reconciled from raw HRIS export | All figures update automatically from Employee Master, Data Quality, and Ticket Tracker sheets
A4: Total Headcount | C4: Active Employees | E4: Terminated Employees | G4: Attrition Rate
A5: =COUNTA('Employee Master'!A2:A121) -> 120 | C5: =COUNTIF('Employee Master'!E2:E121,"Active") -> 103 | E5: =COUNTIF('Employee Master'!E2:E121,"Terminated") -> 17 | G5: =IFERROR(E5/A5,0) -> 0.14166667
A8: Headcount by Department
A9: Department | B9: Headcount | C9: Attrition Count | D9: Attrition %
A10: HR Operations | B10: =COUNTIF('Employee Master'!C2:C121,A10) -> 17 | C10: =COUNTIFS('Employee Master'!C2:C121,A10,'Employee Master'!E2:E121,"Terminated") -> 2 | D10: =IFERROR(C10/B10,0) -> 0.11764706
A11: HRIS & Systems | B11: =COUNTIF('Employee Master'!C2:C121,A11) -> 16 | C11: =COUNTIFS('Employee Master'!C2:C121,A11,'Employee Master'!E2:E121,"Terminated") -> 3 | D11: =IFERROR(C11/B11,0) -> 0.1875
A12: Mobility | B12: =COUNTIF('Employee Master'!C2:C121,A12) -> 14 | C12: =COUNTIFS('Employee Master'!C2:C121,A12,'Employee Master'!E2:E121,"Terminated") -> 4 | D12: =IFERROR(C12/B12,0) -> 0.28571429
A13: Payroll | B13: =COUNTIF('Employee Master'!C2:C121,A13) -> 10 | C13: =COUNTIFS('Employee Master'!C2:C121,A13,'Employee Master'!E2:E121,"Terminated") -> 1 | D13: =IFERROR(C13/B13,0) -> 0.1
A14: Talent Acquisition | B14: =COUNTIF('Employee Master'!C2:C121,A14) -> 12 | C14: =COUNTIFS('Employee Master'!C2:C121,A14,'Employee Master'!E2:E121,"Terminated") -> 1 | D14: =IFERROR(C14/B14,0) -> 0.083333333
A15: Talent Business Advisory | B15: =COUNTIF('Employee Master'!C2:C121,A15) -> 9 | C15: =COUNTIFS('Employee Master'!C2:C121,A15,'Employee Master'!E2:E121,"Terminated") -> 0 | D15: =IFERROR(C15/B15,0) -> 0
A16: Talent Development | B16: =COUNTIF('Employee Master'!C2:C121,A16) -> 14 | C16: =COUNTIFS('Employee Master'!C2:C121,A16,'Employee Master'!E2:E121,"Terminated") -> 2 | D16: =IFERROR(C16/B16,0) -> 0.14285714
A17: Total Rewards | B17: =COUNTIF('Employee Master'!C2:C121,A17) -> 22 | C17: =COUNTIFS('Employee Master'!C2:C121,A17,'Employee Master'!E2:E121,"Terminated") -> 4 | D17: =IFERROR(C17/B17,0) -> 0.18181818
A18: UNASSIGNED - PENDING MANAGER INPUT | B18: =COUNTIF('Employee Master'!C2:C121,A18) -> 6 | C18: =COUNTIFS('Employee Master'!C2:C121,A18,'Employee Master'!E2:E121,"Terminated") -> 0 | D18: =IFERROR(C18/B18,0) -> 0
A20: Performance Rating Distribution
A21: Rating | B21: Count | C21: % of Headcount
A22: Exceeds Expectations | B22: =COUNTIF('Employee Master'!H2:H121,A22) -> 24 | C22: =IFERROR(B22/$A$5,0) -> 0.2
A23: Meets Expectations | B23: =COUNTIF('Employee Master'!H2:H121,A23) -> 48 | C23: =IFERROR(B23/$A$5,0) -> 0.4
A24: Needs Improvement | B24: =COUNTIF('Employee Master'!H2:H121,A24) -> 25 | C24: =IFERROR(B24/$A$5,0) -> 0.20833333
A25: Not Yet Rated | B25: =COUNTIF('Employee Master'!H2:H121,A25) -> 23 | C25: =IFERROR(B25/$A$5,0) -> 0.19166667
A27: Data Quality Summary
A28: Metric | B28: Value
A29: Total Issues Identified | B29: =COUNTA('Data Quality'!A2:A24) -> 23
A30: Issues Resolved | B30: =COUNTIF('Data Quality'!E2:E24,"Resolved") -> 7
A31: Issues Pending | B31: =COUNTIF('Data Quality'!E2:E24,"Pending") -> 16
A32: % Resolved | B32: =IFERROR(B30/B29,0) -> 0.30434783
A34: Ticket Queue Summary
A35: Metric | B35: Value
A36: Total Tickets | B36: =COUNTA('Ticket Tracker'!A2:A11) -> 10
A37: Closed | B37: =COUNTIF('Ticket Tracker'!G2:G11,"Closed") -> 8
A38: Open | B38: =COUNTIF('Ticket Tracker'!G2:G11,"Open") -> 1
A39: In Progress | B39: =COUNTIF('Ticket Tracker'!G2:G11,"In Progress") -> 1
A40: SLA Compliance (Closed Tickets) | B40: =IFERROR(COUNTIF('Ticket Tracker'!K2:K11,"Yes")/COUNTIF('Ticket Tracker'!G2:G11,"Closed"),0) -> 1

Sheet Employee Master
A1: Employee ID | B1: Employee Name | C1: Department | D1: Hire Date | E1: Status | F1: Termination Date | G1: Manager | H1: Performance Rating
A2: EMP1007 | B2: Rohan Agarwal | C2: Total Rewards | D2: 2023-01-21 | E2: Terminated | F2: 2024-08-16 | G2: S. Krishnan | H2: Meets Expectations
A3: EMP1074 | B3: Manoj Bhat | C3: Payroll | D3: 2024-03-06 | E3: Active | G3: S. Krishnan | H3: Meets Expectations
A4: EMP1054 | B4: Anjali Kapoor | C4: Mobility | D4: 2024-09-25 | E4: Active | G4: P. Bose | H4: Not Yet Rated
A5: EMP1003 | B5: Karan Singh | C5: Talent Acquisition | D5: 2025-04-17 | E5: Active | G5: N. Kaur | H5: Not Yet Rated
A6: EMP1050 | B6: Priya Menon | C6: Talent Development | D6: 2021-03-28 | E6: Active | G6: UNASSIGNED | H6: Meets Expectations
A7: EMP1077 | B7: Deepak Sharma | C7: Talent Development | D7: 2021-03-27 | E7: Active | G7: V. Subramaniam | H7: Meets Expectations
A8: EMP1018 | B8: Rajesh Reddy | C8: Total Rewards | D8: 2024-09-10 | E8: Terminated | F8: 2026-04-20 | G8: R. Malhotra | H8: Meets Expectations
A9: EMP1014 | B9: Divya Gupta | C9: HRIS & Systems | D9: 2020-01-08 | E9: Active | G9: S. Krishnan | H9: Meets Expectations
A10: EMP1062 | B10: Amit Bhat | C10: Talent Development | D10: 2023-04-22 | E10: Active | G10: P. Bose | H10: Meets Expectations
A11: EMP1106 | B11: Arjun Pillai | C11: HRIS & Systems | D11: 2023-11-29 | E11: Terminated | G11: V. Subramaniam | H11: Exceeds Expectations
A12: EMP1058 | B12: Ritu Nair | C12: Total Rewards | D12: 2023-07-22 | E12: Terminated | F12: 2024-01-18 | G12: R. Malhotra | H12: Meets Expectations
A13: EMP1027 | B13: Sneha Bhat | C13: Talent Business Advisory | D13: 2023-10-01 | E13: Active | G13: P. Bose | H13: Exceeds Expectations
A14: EMP1065 | B14: Deepak Desai | C14: Mobility | D14: 2025-02-22 | E14: Terminated | F14: 2026-09-15 | G14: A. Fernandes | H14: Needs Improvement
A15: EMP1021 | B15: Vikram Menon | C15: Payroll | D15: 2021-12-21 | E15: Terminated | F15: 2025-11-12 | G15: A. Fernandes | H15: Not Yet Rated
A16: EMP1052 | B16: Pooja Pillai | C16: Mobility | D16: 2025-01-05 | E16: Active | G16: S. Krishnan | H16: Exceeds Expectations
A17: EMP1115 | B17: Suresh Nair | C17: Total Rewards | D17: 2025-03-06 | E17: Active | G17: V. Subramaniam | H17: Needs Improvement
A18: EMP1033 | B18: Vikram Iyer | C18: Total Rewards | D18: 2021-06-10 | E18: Active | G18: V. Subramaniam | H18: Not Yet Rated
A19: EMP1088 | B19: Rohan Singh | C19: Mobility | D19: 2024-06-24 | E19: Terminated | F19: 2026-04-27 | G19: N. Kaur | H19: Needs Improvement
A20: EMP1026 | B20: Anjali Kulkarni | C20: HRIS & Systems | D20: 2021-09-22 | E20: Active | G20: P. Bose | H20: Meets Expectations
A21: EMP1045 | B21: Isha Sharma | C21: HR Operations | D21: 2019-11-05 | E21: Active | G21: V. Subramaniam | H21: Exceeds Expectations
A22: EMP1064 | B22: Priya Agarwal | C22: Talent Development | D22: 2020-05-12 | E22: Terminated | F22: 2026-09-14 | G22: A. Fernandes | H22: Needs Improvement
A23: EMP1066 | B23: Arjun Singh | C23: Total Rewards | D23: 2024-11-05 | E23: Active | G23: N. Kaur | H23: Meets Expectations
A24: EMP1116 | B24: Divya Reddy | C24: HRIS & Systems | D24: 2020-04-26 | E24: Active | G24: P. Bose | H24: Meets Expectations
A25: EMP1114 | B25: Meera Desai | C25: HRIS & Systems | D25: 2020-05-12 | E25: Active | G25: N. Kaur | H25: Not Yet Rated
A26: EMP1071 | B26: Meera Chatterjee | C26: Mobility | D26: 2025-01-13 | E26: Active | G26: A. Fernandes | H26: Needs Improvement
A27: EMP1098 | B27: Vikram Kulkarni | C27: Total Rewards | D27: 2019-12-15 | E27: Active | G27: S. Krishnan | H27: Not Yet Rated
A28: EMP1073 | B28: Amit Gupta | C28: Talent Acquisition | D28: 2023-06-02 | E28: Active | G28: N. Kaur | H28: Exceeds Expectations
A29: EMP1076 | B29: UNKNOWN - PENDING HR CONFIRMATION | C29: HRIS & Systems | D29: 2019-03-21 | E29: Terminated | F29: 2020-01-01 | G29: A. Fernandes | H29: Exceeds Expectations
A30: EMP1060 | B30: Anjali Nair | C30: HR Operations | D30: 2022-03-08 | E30: Terminated | F30: 2026-03-23 | G30: S. Krishnan | H30: Meets Expectations
A31: EMP1036 | B31: Vivek Chandra | C31: Talent Acquisition | D31: 2019-12-02 | E31: Active | G31: N. Kaur | H31: Not Yet Rated
A32: EMP1055 | B32: Arjun Verma | C32: Mobility | D32: 2019-01-07 | E32: Terminated | F32: 2022-07-12 | G32: R. Malhotra | H32: Needs Improvement
A33: EMP1103 | B33: Meera Mehta | C33: HRIS & Systems | D33: 2019-10-19 | E33: Active | G33: R. Malhotra | H33: Not Yet Rated
A34: EMP1085 | B34: Rahul Singh | C34: HR Operations | D34: 2022-02-16 | E34: Active | G34: UNASSIGNED | H34: Needs Improvement
A35: EMP1079 | B35: Ananya Chandra | C35: HR Operations | D35: 2020-11-01 | E35: Active | G35: S. Krishnan | H35: Not Yet Rated
A36: EMP1047 | B36: Priya Joshi | C36: Talent Development | D36: 2021-10-19 | E36: Active | G36: R. Malhotra | H36: Not Yet Rated
A37: EMP1028 | B37: Priya Chatterjee | C37: Talent Business Advisory | D37: 2020-03-23 | E37: Active | G37: A. Fernandes | H37: Meets Expectations
A38: EMP1110 | B38: Rahul Kapoor | C38: HR Operations | D38: 2020-10-20 | E38: Active | G38: P. Bose | H38: Needs Improvement
A39: EMP1023 | B39: Divya Singh | C39: HR Operations | D39: 2022-10-16 | E39: Active | G39: V. Subramaniam | H39: Not Yet Rated
A40: EMP1029 | B40: Vikram Bhat | C40: Payroll | D40: 2022-02-14 | E40: Active | G40: A. Fernandes | H40: Exceeds Expectations
...

Sheet Data Quality
A1: Employee ID | B1: Issue Type | C1: Issue Description | D1: Action Taken | E1: Status
A2: EMP1050 | B2: Missing Manager | C2: Manager field blank in raw export | D2: Flagged as UNASSIGNED; queued for HRBP follow-up | E2: Pending
A3: EMP1106 | B3: Terminated - No Termination Date | C3: Status is Terminated but Termination Date is blank | D3: Flagged for payroll/offboarding team confirmation before next report cycle | E3: Pending
A4: EMP1065 | B4: Status Contradiction | C4: Status is Active but a Termination Date is present | D4: Corrected Status to Terminated using Termination Date as source of truth (data precedence rule) | E4: Resolved
A5: EMP1064 | B5: Status Contradiction | C5: Status is Active but a Termination Date is present | D5: Corrected Status to Terminated using Termination Date as source of truth (data precedence rule) | E5: Resolved
A6: EMP1076 | B6: Missing Employee Name | C6: Name field blank in raw export | D6: Flagged as UNKNOWN - PENDING HR CONFIRMATION; routed to source system owner | E6: Pending
A7: EMP1085 | B7: Missing Manager | C7: Manager field blank in raw export | D7: Flagged as UNASSIGNED; queued for HRBP follow-up | E7: Pending
A8: EMP1110 | B8: Duplicate Employee ID | C8: Employee ID EMP1110 appears 2 times in raw export | D8: Retained most complete record per SOP; removed duplicate row(s) | E8: Resolved
A9: EMP1100 | B9: Duplicate Employee ID | C9: Employee ID EMP1100 appears 2 times in raw export | D9: Retained most complete record per SOP; removed duplicate row(s) | E9: Resolved
A10: EMP1091 | B10: Missing Department | C10: Department field blank in raw export | D10: Flagged as UNASSIGNED - PENDING MANAGER INPUT; escalated to reporting manager | E10: Pending
A11: EMP1096 | B11: Missing Department | C11: Department field blank in raw export | D11: Flagged as UNASSIGNED - PENDING MANAGER INPUT; escalated to reporting manager | E11: Pending
A12: EMP1102 | B12: Missing Manager | C12: Manager field blank in raw export | D12: Flagged as UNASSIGNED; queued for HRBP follow-up | E12: Pending
... A24: EMP1117 | B24: Missing Department | C24: Department field blank in raw export | D24: Flagged as UNASSIGNED - PENDING MANAGER INPUT; escalated to reporting manager | E24: Pending

Sheet Ticket Tracker
A1: Ticket ID | B1: Date Opened | C1: Requestor | D1: Category | E1: Description | F1: Priority | G1: Status | H1: Resolution Notes | I1: Date Closed | J1: SLA (Days) | K1: SLA Met (<=3 Days)
A2: TCK-1001 | B2: 2026-08-03 | C2: HRBP - Mehta | D2: Data Correction | E2: Update department for EMP1042 from blank to Talent Acquisition | F2: Medium | G2: Closed | H2: Confirmed via transfer email; simulated HRIS update to Talent Acquisition | I2: 2026-08-04 | J2: =IF(I2="","",IFERROR(I2-B2,"")) -> 1 | K2: =IF(J2="","",IF(J2<=3,"Yes","No")) -> Yes
A3: TCK-1002 | B3: 2026-08-05 | C3: Employee Self-Service | D3: Data Correction | E3: Employee name shows blank in system after recent name change | F3: High | G3: Closed | H3: Verified via HR file; simulated correction of name field in HRIS record | I3: 2026-08-05 | J3: =IF(I3="","",IFERROR(I3-B3,"")) -> 0 | K3: =IF(J3="","",IF(J3<=3,"Yes","No")) -> Yes
A4: TCK-1003 | B4: 2026-08-06 | C4: Payroll Team | D4: Escalation | E4: Employee status shows Active but has a termination date on file | F4: High | G4: Closed | H4: Applied data precedence rule, simulated status update to Terminated, notified payroll | I4: 2026-08-07 | J4: =IF(I4="","",IFERROR(I4-B4,"")) -> 1 | K4: =IF(J4="","",IF(J4<=3,"Yes","No")) -> Yes
A5: TCK-1004 | B5: 2026-08-10 | C5: HRBP - Rao | D5: Reporting Request | E5: Ad hoc attrition report needed for Q3 board deck | F5: Medium | G5: Closed | H5: Delivered attrition-by-department report same week | I5: 2026-08-12 | J5: =IF(I5="","",IFERROR(I5-B5,"")) -> 2 | K5: =IF(J5="","",IF(J5<=3,"Yes","No")) -> Yes
A6: TCK-1005 | B6: 2026-08-11 | C6: HRIS Systems Team | D6: Data Migration | E6: Validate 120 records post system migration for duplicates | F6: High | G6: Closed | H6: Found and resolved 4 duplicate IDs in simulated dataset; see audit findings log | I6: 2026-08-13 | J6: =IF(I6="","",IFERROR(I6-B6,"")) -> 2 | K6: =IF(J6="","",IF(J6<=3,"Yes","No")) -> Yes
A7: TCK-1006 | B7: 2026-08-14 | C7: Manager - S. Krishnan | D7: Data Correction | E7: Manager field is blank for a direct report | F7: Low | G7: Closed | H7: Simulated HRIS update to manager field per org chart confirmation | I7: 2026-08-15 | J7: =IF(I7="","",IFERROR(I7-B7,"")) -> 1 | K7: =IF(J7="","",IF(J7<=3,"Yes","No")) -> Yes
A8: TCK-1007 | B8: 2026-08-18 | C8: HRBP - Iyer | D8: Reporting Request | E8: Monthly headcount report request for Total Rewards dept | F8: Low | G8: Closed | H8: Delivered per standard monthly SOP | I8: 2026-08-19 | J8: =IF(I8="","",IFERROR(I8-B8,"")) -> 1 | K8: =IF(J8="","",IF(J8<=3,"Yes","No")) -> Yes
A9: TCK-1008 | B9: 2026-08-20 | C9: Employee Self-Service | D9: Data Correction | E9: Termination date missing for an employee marked Terminated | F9: Medium | G9: Open | H9: Awaiting confirmation from offboarding team | J9: =IF(I9="","",IFERROR(I9-B9,"")) | K9: =IF(J9="","",IF(J9<=3,"Yes","No"))
A10: TCK-1009 | B10: 2026-08-22 | C10: HRIS Systems Team | D10: System Testing | E10: UAT support needed for new HRIS field mapping | F10: Medium | G10: In Progress | H10: Testing in progress on simulated dataset; 2 of 5 test cases completed | J10: =IF(I10="","",IFERROR(I10-B10,"")) | K10: =IF(J10="","",IF(J10<=3,"Yes","No"))
A11: TCK-1010 | B11: 2026-08-25 | C11: HRBP - Bose | D11: Data Correction | E11: Duplicate employee ID identified during onboarding | F11: High | G11: Closed | H11: Simulated merge of duplicate records; retained most complete record | I11: 2026-08-26 | J11: =IF(I11="","",IFERROR(I11-B11,"")) -> 1 | K11: =IF(J11="","",IF(J11<=3,"Yes","No")) -> Yes
